<?xml version="1.0"?>

  <robot name="Block">
    <link name="base_link">
      <visual>
        <geometry> <box size="0.2 0.2 0.2" />  </geometry>
        <material name="green"><color rgba="0 1 0 1" />  </material>
      </visual>
    </link>

    <link name="upper_link">
      <inertial>
        <origin xyz="0 0 0" rpy="0 0 0" />
        <mass value="1" />
        <inertia ixx="1" ixy="0" ixz="0" iyy="0.083" iyz="0" izz="1" />
      </inertial>
      <visual>
           <origin xyz="0.25 0.25 0.25"/>
           <geometry> <box size="0.5 0.5 0.5" /></geometry>
           <material name="red">  <color rgba="1 0 0 1" /></material>
      </visual>
    </link>
    <joint name="base_link" type="floating">
      <parent link="base_link"/>
      <child link="upper_link"/>
      <origin xyz="1.0 0.0 0.0" rpy="0.0 -0.0 0.0"/>
      <axis xyz="0.0 1.0 0.0"/>
      <limit effort="Inf" velocity="Inf"/>
    </joint>


  </robot>
