<?xml version="1.0"?>

<robot name="DoublePendulum">
  <link name="base_link">
  </link>

  <link name="upper_link">
    <inertial>
      <origin xyz="0 0 0.333" rpy="0 0 0" />
      <mass value="1" />
      <inertia ixx="1" ixy="0" ixz="0" iyy="0.083" iyz="0" izz="1" />
    </inertial>
    <visual>
      <origin xyz="0 0 -0.5" rpy="0 0 0" />
      <geometry> <box size="0.05 0.05 1.0" /></geometry>
      <material name="red">
	       <color rgba="1 0 0 1" />
      </material>
    </visual>
  </link>
  <joint name="shoulder" type="continuous">
    <parent link="base_link" />
    <child link="upper_link" />
    <origin xyz="0 0 0" />
    <axis xyz="0 1 0" />
  </joint>

  <link name="lower_link">
    <inertial>
      <origin xyz="0 0 -1" rpy="0 0 0" />
      <mass value="1" />
      <inertia ixx="1" ixy="0" ixz="0" iyy="0.33" iyz="0" izz="1" />
    </inertial>
    <visual>
      <origin xyz="0 0 -1" rpy="0 0 0" />
      <geometry>
         <cylinder length="2" radius=".05" />
      </geometry>
      <material name="blue">
	       <color rgba="0 0 1 1" />
      </material>
    </visual>
  </link>



  <joint name="elbow" type="continuous">
    <parent link="upper_link" />
    <child link="lower_link" />
    <origin xyz="0 .1 -1" />
    <axis xyz="0 1 0" />
    <dynamics damping="0.1" />
  </joint>

  <link name="endeffector">
    <inertial>
      <origin xyz="0.0 0 -1" rpy="0 0 0" />
      <mass value="0" />
      <inertia ixx="0" ixy="0" ixz="0" iyy="0" iyz="0" izz="0" />
    </inertial>
    <visual>
      <origin xyz="0.0 0 0 "/>
      <geometry>  <box size="0.05 0.05 0.05" /> </geometry>
      <material name="green"> <color rgba="0 1 0 1" /> </material>
    </visual>
  </link>

  <joint name="endjoint" type="fixed">
    <parent link="lower_link" />
    <child link="endeffector" />
    <origin xyz="0.0 0.0 -2" rpy="0.0 0 0 "/>
  </joint>
</robot>
